Workbook

Sheet Orçamento_Padrão
D4: Olá Cliente, GF!
B8: Após a devolução, seu carro passou por uma inspeção completa, onde foi verificado as condições de uso e as inconsistencias apontadas no checklist. Segue o detalhamento dessa devolução, incluindo os valores dos serviços necessários para reparos das avarias identificadas, conforme as condições do seu contrato.
B14: LOCALIZA RENT A CAR S/A Av. Bernardo Vasconcelos, 377 - Cachoeirinha CEP: 31150-000 - Belo Horizonte - MG CNPJ: 16.670.085/0001-55 INSC. MUN.: 138.256/001-7
B18: Cliente | C18: =_xlfn.XLOOKUP(C20,[1]Planilha1!$B:$B,[1]Planilha1!$G:$G,"") -> 0 | E18: VALOR TOTAL
B19: Contrato: | C19: =_xlfn.XLOOKUP(C20,[1]Planilha1!$B:$B,[1]Planilha1!$F:$F,"") -> 0 | E19: =SUM(F61+F104) -> 0
B20: Placa:
B21: Modelo: | C21: =_xlfn.XLOOKUP(C20,[1]Planilha1!$B:$B,[1]Planilha1!$D:$D,"") -> 0
B23: Observações:
B26: Descrição: Avarias de devolução
B29: Itens de serviços relacionados a esta cobrança:
B31: Nº Item | C31: Tipo de Despesa | D31: Descrição | E31: Qtd. | F31: Valor do Serviço/Item
B32: =IF(D32>"",1,"") | C32: =IF(D32>"","Avaria de Devolução","") | E32: 1 | H32: =IFERROR(_xlfn.XLOOKUP(D32,[2]LPU!$C:$C,[2]LPU!$D:$D)*Orçamento_Padrão!E32,F32) -> 0
B33: =IF(D33>"",SUM(B32+1),"") | C33: =IF(D33>"","Avarias de Devolução","") | E33: 1 | H33: =IFERROR(_xlfn.XLOOKUP(D33,[2]LPU!$C:$C,[2]LPU!$D:$D)*Orçamento_Padrão!E33,F33) -> 0
B34: =IF(D34>"",SUM(B33+1),"") | C34: =IF(D34>"","Avarias de Devolução","") | E34: 1 | H34: =IFERROR(_xlfn.XLOOKUP(D34,[2]LPU!$C:$C,[2]LPU!$D:$D)*Orçamento_Padrão!E34,F34) -> 0
B35: =IF(D35>"",SUM(B34+1),"") | C35: =IF(D35>"","Avarias de Devolução","") | E35: 1 | H35: =IFERROR(_xlfn.XLOOKUP(D35,[2]LPU!$C:$C,[2]LPU!$D:$D)*Orçamento_Padrão!E35,F35) -> 0
B36: =IF(D36>"",SUM(B35+1),"") | C36: =IF(D36>"","Avarias de Devolução","") | E36: 1 | H36: =IFERROR(_xlfn.XLOOKUP(D36,[2]LPU!$C:$C,[2]LPU!$D:$D)*Orçamento_Padrão!E36,F36) -> 0
B37: =IF(D37>"",SUM(B36+1),"") | C37: =IF(D37>"","Avarias de Devolução","") | E37: 1 | H37: =IFERROR(_xlfn.XLOOKUP(D37,[2]LPU!$C:$C,[2]LPU!$D:$D)*Orçamento_Padrão!E37,F37) -> 0
B38: =IF(D38>"",SUM(B37+1),"") | C38: =IF(D38>"","Avarias de Devolução","") | E38: 1 | H38: =IFERROR(_xlfn.XLOOKUP(D38,[2]LPU!$C:$C,[2]LPU!$D:$D)*Orçamento_Padrão!E38,F38) -> 0
B39: =IF(D39>"",SUM(B38+1),"") | C39: =IF(D39>"","Avarias de Devolução","") | E39: 1 | H39: =IFERROR(_xlfn.XLOOKUP(D39,[2]LPU!$C:$C,[2]LPU!$D:$D)*Orçamento_Padrão!E39,F39) -> 0
B40: =IF(D40>"",SUM(B39+1),"") | C40: =IF(D40>"","Avarias de Devolução","") | E40: 1 | H40: =IFERROR(_xlfn.XLOOKUP(D40,[2]LPU!$C:$C,[2]LPU!$D:$D)*Orçamento_Padrão!E40,F40) -> 0
B41: =IF(D41>"",SUM(B40+1),"") | C41: =IF(D41>"","Avarias de Devolução","") | E41: 1 | H41: =IFERROR(_xlfn.XLOOKUP(D41,[2]LPU!$C:$C,[2]LPU!$D:$D)*Orçamento_Padrão!E41,F41) -> 0
B42: =IF(D42>"",SUM(B41+1),"") | C42: =IF(D42>"","Avarias de Devolução","") | E42: 1 | H42: =IFERROR(_xlfn.XLOOKUP(D42,[2]LPU!$C:$C,[2]LPU!$D:$D)*Orçamento_Padrão!E42,F42) -> 0
B43: =IF(D43>"",SUM(B42+1),"") | C43: =IF(D43>"","Avarias de Devolução","") | E43: 1 | H43: =IFERROR(_xlfn.XLOOKUP(D43,[2]LPU!$C:$C,[2]LPU!$D:$D)*Orçamento_Padrão!E43,F43) -> 0
B44: =IF(D44>"",SUM(B43+1),"") | C44: =IF(D44>"","Avarias de Devolução","") | E44: 1 | H44: =IFERROR(_xlfn.XLOOKUP(D44,[2]LPU!$C:$C,[2]LPU!$D:$D)*Orçamento_Padrão!E44,F44) -> 0
B45: =IF(D45>"",SUM(B44+1),"") | C45: =IF(D45>"","Avarias de Devolução","") | H45: =IFERROR(_xlfn.XLOOKUP(D45,[2]LPU!$C:$C,[2]LPU!$D:$D)*Orçamento_Padrão!E45,F45) -> 0
B46: =IF(D46>"",SUM(B45+1),"") | C46: =IF(D46>"","Avarias de Devolução","") | H46: =IFERROR(_xlfn.XLOOKUP(D46,[2]LPU!$C:$C,[2]LPU!$D:$D)*Orçamento_Padrão!E46,F46) -> 0
B47: =IF(D47>"",SUM(B46+1),"") | C47: =IF(D47>"","Avarias de Devolução","") | H47: =IFERROR(_xlfn.XLOOKUP(D47,[2]LPU!$C:$C,[2]LPU!$D:$D)*Orçamento_Padrão!E47,F47) -> 0
B48: =IF(D48>"",SUM(B47+1),"") | C48: =IF(D48>"","Avarias de Devolução","") | H48: =IFERROR(_xlfn.XLOOKUP(D48,[2]LPU!$C:$C,[2]LPU!$D:$D)*Orçamento_Padrão!E48,F48) -> 0
B49: =IF(D49>"",SUM(B48+1),"") | C49: =IF(D49>"","Avarias de Devolução","") | H49: =IFERROR(_xlfn.XLOOKUP(D49,[2]LPU!$C:$C,[2]LPU!$D:$D)*Orçamento_Padrão!E49,F49) -> 0
B50: =IF(D50>"",SUM(B49+1),"") | C50: =IF(D50>"","Avarias de Devolução","") | H50: =IFERROR(_xlfn.XLOOKUP(D50,[2]LPU!$C:$C,[2]LPU!$D:$D)*Orçamento_Padrão!E50,F50) -> 0
B51: =IF(D51>"",SUM(B50+1),"") | C51: =IF(D51>"","Avarias de Devolução","") | H51: =IFERROR(_xlfn.XLOOKUP(D51,[2]LPU!$C:$C,[2]LPU!$D:$D)*Orçamento_Padrão!E51,F51) -> 0
B52: =IF(D52>"",SUM(B51+1),"") | C52: =IF(D52>"","Avarias de Devolução","") | H52: =IFERROR(_xlfn.XLOOKUP(D52,[2]LPU!$C:$C,[2]LPU!$D:$D)*Orçamento_Padrão!E52,F52) -> 0
B53: =IF(D53>"",SUM(B52+1),"") | C53: =IF(D53>"","Avarias de Devolução","") | H53: =IFERROR(_xlfn.XLOOKUP(D53,[2]LPU!$C:$C,[2]LPU!$D:$D)*Orçamento_Padrão!E53,F53) -> 0
B54: =IF(D54>"",SUM(B53+1),"") | C54: =IF(D54>"","Avarias de Devolução","") | H54: =IFERROR(_xlfn.XLOOKUP(D54,[2]LPU!$C:$C,[2]LPU!$D:$D)*Orçamento_Padrão!E54,F54) -> 0
B55: =IF(D55>"",SUM(B54+1),"") | C55: =IF(D55>"","Avarias de Devolução","") | H55: =IFERROR(_xlfn.XLOOKUP(D55,[2]LPU!$C:$C,[2]LPU!$D:$D)*Orçamento_Padrão!E55,F55) -> 0
B56: =IF(D56>"",SUM(B55+1),"") | C56: =IF(D56>"","Avarias de Devolução","") | H56: =IFERROR(_xlfn.XLOOKUP(D56,[2]LPU!$C:$C,[2]LPU!$D:$D)*Orçamento_Padrão!E56,F56) -> 0
... B59: =IF(D59>"",SUM(B58+1),"") | C59: =IF(D59>"","Avarias de Devolução","") | H59: =IFERROR(_xlfn.XLOOKUP(D59,[2]LPU!$C:$C,[2]LPU!$D:$D)*Orçamento_Padrão!E59,F59) -> 0
E61: Total | F61: =SUM(F32:F59) -> 0 | H61: =IFERROR(_xlfn.XLOOKUP(#REF!,[2]LPU!$C:$C,[2]LPU!$D:$D)*Orçamento_Padrão!E61,F61) -> 0
B64: Itens de cotação de peça relacionados a esta cobrança: | H64: =IFERROR(_xlfn.XLOOKUP(#REF!,[2]LPU!$C:$C,[2]LPU!$D:$D)*Orçamento_Padrão!E64,F64) -> 0
H65: =IFERROR(_xlfn.XLOOKUP(#REF!,[2]LPU!$C:$C,[2]LPU!$D:$D)*Orçamento_Padrão!E65,F65) -> 0
...

Sheet LPU
A1: TIPO DE SERVIÇOS | B1: DESCRIÇÃO PARA CARTA DE AVARIAS | C1: VALOR
A2: Bateria | B2: Troca de Bateria Automotiva | C2: SOB CONSULTA
A3: Chave principal | B3: Reposição da Chave Principal do Veículo | C3: SOB CONSULTA
A4: Chave reserva | B4: Reposição da Chave Reserva do Veículo | C4: SOB CONSULTA
A5: Macaco (veiculo pesado) | B5: Reposição de macaco automotivo | C5: SOB CONSULTA
A6: Chave de Roda | B6: Reposição de Chave de Roda | C6: R$80,00
A7: Mão de obra para troca de peças fixas da lataria que necessitam de solda (Teto, Laterais, Colunas, Caixa de ar) | B7: Mão de obra para troca de teto com solda | C7: R$750,00
A8: Mão de obra para troca de peças fixas da lataria que necessitam de solda (Teto, Laterais, Colunas, Caixa de ar) | B8: Mão de obra para troca de lateral esquerda com solda | C8: R$750,00
A9: Mão de obra para troca de peças fixas da lataria que necessitam de solda (Teto, Laterais, Colunas, Caixa de ar) | B9: Mão de obra para troca de lateral direita com solda | C9: R$750,00
A10: Mão de obra para troca de peças fixas da lataria que necessitam de solda (Teto, Laterais, Colunas, Caixa de ar) | B10: Mão de obra para troca de coluna dianteira esquerda com solda | C10: R$750,00
A11: Mão de obra para troca de peças fixas da lataria que necessitam de solda (Teto, Laterais, Colunas, Caixa de ar) | B11: Mão de obra para troca de coluna dianteira direita com solda | C11: R$750,00
A12: Mão de obra para troca de peças fixas da lataria que necessitam de solda (Teto, Laterais, Colunas, Caixa de ar) | B12: Mão de obra para troca de coluna traseira esquerda com solda | C12: R$750,00
... A78: Higienização Interna | B78: Serviço de Higienização Interna | C78: R$250,00
A79: Higienização Interna (em caso de sujeira severa será acrescentado R$150) | B79: Serviço de Higienização Interna (Sujeira Severa) | C79: 400
A80: Polimento (Veículos pequenos e médios) | B80: Serviço de Polimento | C80: R$250,00
A81: Martelinho de ouro (Amassado que não afetou a pintura) | B81: Serviço de martelinho de ouro – Capô | C81: R$230,00
A82: Martelinho de ouro (Amassado que não afetou a pintura) | B82: Serviço de martelinho de ouro – Teto | C82: R$230,00
A83: Martelinho de ouro (Amassado que não afetou a pintura) | B83: Serviço de martelinho de ouro – Porta dianteira esquerda | C83: R$230,00
A84: Martelinho de ouro (Amassado que não afetou a pintura) | B84: Serviço de martelinho de ouro – Porta dianteira direita | C84: R$230,00
A85: Martelinho de ouro (Amassado que não afetou a pintura) | B85: Serviço de martelinho de ouro – Porta traseira esquerda | C85: R$230,00
A86: Martelinho de ouro (Amassado que não afetou a pintura) | B86: Serviço de martelinho de ouro – Porta traseira direita | C86: R$230,00
A87: Martelinho de ouro (Amassado que não afetou a pintura) | B87: Serviço de martelinho de ouro – Paralama dianteiro esquerdo | C87: R$230,00
A88: Martelinho de ouro (Amassado que não afetou a pintura) | B88: Serviço de martelinho de ouro – Paralama dianteiro direito | C88: R$230,00
A89: Martelinho de ouro (Amassado que não afetou a pintura) | B89: Serviço de martelinho de ouro – Paralama traseiro esquerdo | C89: R$230,00
A90: Martelinho de ouro (Amassado que não afetou a pintura) | B90: Serviço de martelinho de ouro – Paralama traseiro direito | C90: R$230,00
A91: Martelinho de ouro (Amassado que não afetou a pintura) | B91: Serviço de martelinho de ouro – Tampa do porta-malas | C91: R$230,00
... A137: Mão de obra para troca de peças moveis que não necessitam de solda (Parachoques, Paralamas, Porta, Capô, Tampa traseira, Lanternas, Farois e Retrovisores) | B137: Mão de obra para troca de Farol direito | C137: R$140,00
A138: Mão de obra para troca de peças moveis que não necessitam de solda (Parachoques, Paralamas, Porta, Capô, Tampa traseira, Lanternas, Farois e Retrovisores) | B138: Mão de obra para troca de Farol de neblina direito
A139: Mão de obra para troca de peças moveis que não necessitam de solda (Parachoques, Paralamas, Porta, Capô, Tampa traseira, Lanternas, Farois e Retrovisores) | B139: Mão de obra para troca de Farol de neblina esquerdo
A140: Mão de obra para troca de peças moveis que não necessitam de solda (Parachoques, Paralamas, Porta, Capô, Tampa traseira, Lanternas, Farois e Retrovisores) | B140: Mão de obra para troca de Retrovisor esquerdo | C140: R$140,00
A141: Mão de obra para troca de peças moveis que não necessitam de solda (Parachoques, Paralamas, Porta, Capô, Tampa traseira, Lanternas, Farois e Retrovisores) | B141: Mão de obra para troca de Retrovisor direito | C141: R$140,00
A142: Mão de obra para troca de peças moveis que não necessitam de solda (Parachoques, Paralamas, Porta, Capô, Tampa traseira, Lanternas, Farois e Retrovisores) | B142: Mão de obra para troca de repetidor de seta direito | C142: R$140,00
A143: Mão de obra para troca de peças moveis que não necessitam de solda (Parachoques, Paralamas, Porta, Capô, Tampa traseira, Lanternas, Farois e Retrovisores) | B143: Mão de obra para troca de repetidor de seta esquerdo | C143: R$140,00
A144: Martelinho de ouro (por peça, com até 3 mossas) | B144: Serviço de martelinho de ouro – Capô | C144: R$140,00
A145: Martelinho de ouro (por peça, com até 3 mossas) | B145: Serviço de martelinho de ouro – Teto | C145: R$140,00
A146: Martelinho de ouro (por peça, com até 3 mossas) | B146: Serviço de martelinho de ouro – Porta dianteira esquerda | C146: R$140,00
A147: Martelinho de ouro (por peça, com até 3 mossas) | B147: Serviço de martelinho de ouro – Porta dianteira direita | C147: R$140,00
A148: Martelinho de ouro (por peça, com até 3 mossas) | B148: Serviço de martelinho de ouro – Porta traseira esquerda | C148: R$140,00
A149: Martelinho de ouro (por peça, com até 3 mossas) | B149: Serviço de martelinho de ouro – Porta traseira direita | C149: R$140,00
A150: Martelinho de ouro (por peça, com até 3 mossas) | B150: Serviço de martelinho de ouro – Paralama dianteiro esquerdo | C150: R$140,00
...

Sheet Detalhamento_Avarias
B2: Evidências da Cobrança
B7: Cliente | C7: =Orçamento_Padrão!C18 -> 0 | K7: VALOR TOTAL
B8: Contrato: | C8: =Orçamento_Padrão!C19 -> 0 | K8: =Orçamento_Padrão!E19 -> 0
B9: Placa: | C9: =Orçamento_Padrão!C20 -> 0
B10: Modelo: | C10: =Orçamento_Padrão!C21 -> 0
B14: 1 | C14: =Orçamento_Padrão!D32 -> 0 | J14: Valor | K14: =Orçamento_Padrão!F32 -> 0
B30: 2 | C30: =Orçamento_Padrão!D33 -> 0 | J30: Valor | K30: =Orçamento_Padrão!F33 -> 0
B46: 3 | C46: =Orçamento_Padrão!D34 -> 0 | J46: Valor | K46: =Orçamento_Padrão!F34 -> 0
B62: 4 | C62: =Orçamento_Padrão!D35 -> 0 | J62: Valor | K62: =Orçamento_Padrão!F35 -> 0
B82: 5 | C82: =Orçamento_Padrão!D36 -> 0 | J82: Valor | K82: =Orçamento_Padrão!F36 -> 0
B98: 6 | C98: =Orçamento_Padrão!D37 -> 0 | J98: Valor | K98: =Orçamento_Padrão!F37 -> 0
B114: 7 | C114: =Orçamento_Padrão!D38 -> 0 | J114: Valor | K114: =Orçamento_Padrão!F38 -> 0
B130: 8 | C130: =Orçamento_Padrão!D39 -> 0 | J130: Valor | K130: =Orçamento_Padrão!F39 -> 0
B146: 9 | C146: =Orçamento_Padrão!D40 -> 0 | J146: Valor | K146: =Orçamento_Padrão!F67 -> 0
B162: 10 | C162: =Orçamento_Padrão!D41 -> 0 | J162: Valor | K162: =Orçamento_Padrão!F68 -> 0
B178: 11 | C178: =Orçamento_Padrão!D67 -> 0 | J178: Valor | K178: =Orçamento_Padrão!F42 -> 0
B194: 12 | C194: =Orçamento_Padrão!D68 -> 0 | J194: Valor | K194: =Orçamento_Padrão!F43 -> 0
B210: 13 | C210: =Orçamento_Padrão!D69 -> 0 | J210: Valor | K210: =Orçamento_Padrão!F44 -> 0
B226: 14 | C226: =Orçamento_Padrão!D70 -> 0 | J226: Valor | K226: =Orçamento_Padrão!F64 -> 0
B242: 15 | C242: =Orçamento_Padrão!D71 -> 0 | J242: Valor | K242: =Orçamento_Padrão!F65 -> 0
B258: 16 | C258: =Orçamento_Padrão!D72 -> 0 | J258: Valor | K258: =Orçamento_Padrão!F66 -> Valor da peça/Item
B274: 17 | C274: =Orçamento_Padrão!D73 -> 0 | J274: Valor | K274: =Orçamento_Padrão!#REF! -> #REF!
B290: 18 | C290: =Orçamento_Padrão!D74 -> 0 | J290: Valor | K290: =Orçamento_Padrão!F67 -> 0
B306: 19 | C306: =Orçamento_Padrão!D75 -> 0 | J306: Valor | K306: =Orçamento_Padrão!F98 -> 0
B322: 21 | C322: =Orçamento_Padrão!D76 -> 0 | J322: Valor | K322: =Orçamento_Padrão!F76 -> 0
B324: 22 | C324: =Orçamento_Padrão!D77 -> 0 | J324: Valor | K324: =Orçamento_Padrão!F77 -> 0
B326: 24 | C326: =Orçamento_Padrão!D78 -> 0 | J326: Valor | K326: =Orçamento_Padrão!F78 -> 0

Sheet Checklist
B7: =_xlfn.XLOOKUP(B12,[3]Base_de_Trabalho!$D:$D,[3]Base_de_Trabalho!$P:$P,"") -> TITAN PNEUS DO BRASIL LTDA
B8: =_xlfn.XLOOKUP(B12,[3]Base_de_Trabalho!$D:$D,[3]Base_de_Trabalho!$O:$O,"") -> SAO0902/15
B12: RUP2D06
B13: =_xlfn.XLOOKUP($B$12,[3]Base_de_Trabalho!$D:$D,[3]Base_de_Trabalho!$I:$I,"") -> SW4 DIAMOND 7L 2.8 16V TURBO DIE 4X4 4P C/AR - AUTOMÁTICO BLINDADO
B14: =_xlfn.XLOOKUP(B12,[3]Base_de_Trabalho!$D:$D,[3]Base_de_Trabalho!$J:$J,"") -> BRANCO PEROLIZADO COM TETO PRETO
C20: Polimento | G20: 250
