Workbook

Sheet Orçamento_Padrão
C2: LOCALIZA RENT A CAR S/A Av. Bernardo Vasconcelos, 377 - Cachoeirinha CEP: 31150-000 - Belo Horizonte - MG CNPJ: 16.670.085/0001-55 INSC. MUN.: 138.256/001-7
B7: Cliente | C7: xxxx
B8: Contrato:
B10: Placa: | C10: RTB4D20 | E10: VALOR TOTAL
B11: Modelo: | C11: MOBI LIKE 1.0 8V FLEX 4P C/AR | E11: =F59 -> 760
B12: Cor: | C12: CINZA SILVERSTONE
B15: Observações:
B18: Descrição
B19: Avarias de devolução
B21: ITENS DA SOLICITAÇÃO DE SERVIÇOS RELACIONADOS A ESTA COBRANÇA
B23: Nº Item | C23: Tipo de Despesa | D23: Descrição | E23: Qtd. | F23: Valor do Serviço/Item
B24: 1 | C24: Avarias de Devolução | D24: Recuperação e pintura porta dianteira direita | E24: 1 | F24: 420 | H24: =IFERROR(_xlfn.XLOOKUP(D24,[1]LPU!$C:$C,[1]LPU!$D:$D)*Orçamento_Padrão!E24,F24) -> 420
B25: 2 | C25: Avarias de Devolução | D25: Pintura porta dianteira direita | E25: 1 | F25: 340 | H25: =IFERROR(_xlfn.XLOOKUP(D25,[1]LPU!$C:$C,[1]LPU!$D:$D)*Orçamento_Padrão!E25,F25) -> 340
H26: =IFERROR(_xlfn.XLOOKUP(D26,[1]LPU!$C:$C,[1]LPU!$D:$D)*Orçamento_Padrão!E26,F26) -> 0
B27: =IF(D27>"",SUM(B26+1),"") | C27: =IF(D27>"","Avarias de Devolução","") | H27: =IFERROR(_xlfn.XLOOKUP(D27,[1]LPU!$C:$C,[1]LPU!$D:$D)*Orçamento_Padrão!E27,F27) -> 0
B28: =IF(D28>"",SUM(B27+1),"") | C28: =IF(D28>"","Avarias de Devolução","") | H28: =IFERROR(_xlfn.XLOOKUP(D28,[1]LPU!$C:$C,[1]LPU!$D:$D)*Orçamento_Padrão!E28,F28) -> 0
B29: =IF(D29>"",SUM(B28+1),"") | C29: =IF(D29>"","Avarias de Devolução","") | H29: =IFERROR(_xlfn.XLOOKUP(D29,[1]LPU!$C:$C,[1]LPU!$D:$D)*Orçamento_Padrão!E29,F29) -> 0
B30: =IF(D30>"",SUM(B29+1),"") | C30: =IF(D30>"","Avarias de Devolução","") | H30: =IFERROR(_xlfn.XLOOKUP(D30,[1]LPU!$C:$C,[1]LPU!$D:$D)*Orçamento_Padrão!E30,F30) -> 0
B31: =IF(D31>"",SUM(B30+1),"") | C31: =IF(D31>"","Avarias de Devolução","") | H31: =IFERROR(_xlfn.XLOOKUP(D31,[1]LPU!$C:$C,[1]LPU!$D:$D)*Orçamento_Padrão!E31,F31) -> 0
B32: =IF(D32>"",SUM(B31+1),"") | C32: =IF(D32>"","Avarias de Devolução","") | H32: =IFERROR(_xlfn.XLOOKUP(D32,[1]LPU!$C:$C,[1]LPU!$D:$D)*Orçamento_Padrão!E32,F32) -> 0
B33: =IF(D33>"",SUM(B32+1),"") | C33: =IF(D33>"","Avarias de Devolução","") | H33: =IFERROR(_xlfn.XLOOKUP(D33,[1]LPU!$C:$C,[1]LPU!$D:$D)*Orçamento_Padrão!E33,F33) -> 0
B34: =IF(D34>"",SUM(B33+1),"") | C34: =IF(D34>"","Avarias de Devolução","") | H34: =IFERROR(_xlfn.XLOOKUP(D34,[1]LPU!$C:$C,[1]LPU!$D:$D)*Orçamento_Padrão!E34,F34) -> 0
B35: =IF(D35>"",SUM(B34+1),"") | C35: =IF(D35>"","Avarias de Devolução","") | H35: =IFERROR(_xlfn.XLOOKUP(D35,[1]LPU!$C:$C,[1]LPU!$D:$D)*Orçamento_Padrão!E35,F35) -> 0
B36: =IF(D36>"",SUM(B35+1),"") | C36: =IF(D36>"","Avarias de Devolução","") | H36: =IFERROR(_xlfn.XLOOKUP(D36,[1]LPU!$C:$C,[1]LPU!$D:$D)*Orçamento_Padrão!E36,F36) -> 0
B37: =IF(D37>"",SUM(B36+1),"") | C37: =IF(D37>"","Avarias de Devolução","") | H37: =IFERROR(_xlfn.XLOOKUP(D37,[1]LPU!$C:$C,[1]LPU!$D:$D)*Orçamento_Padrão!E37,F37) -> 0
B38: =IF(D38>"",SUM(B37+1),"") | C38: =IF(D38>"","Avarias de Devolução","") | H38: =IFERROR(_xlfn.XLOOKUP(D38,[1]LPU!$C:$C,[1]LPU!$D:$D)*Orçamento_Padrão!E38,F38) -> 0
... B57: =IF(D57>"",SUM(B56+1),"") | C57: =IF(D57>"","Avarias de Devolução","") | H57: =IFERROR(_xlfn.XLOOKUP(D57,[1]LPU!$C:$C,[1]LPU!$D:$D)*Orçamento_Padrão!E57,F57) -> 0
H58: =IFERROR(_xlfn.XLOOKUP(D58,[1]LPU!$C:$C,[1]LPU!$D:$D)*Orçamento_Padrão!E58,F58) -> 0
F59: =SUM(F24:F25) -> 760 | H59: =IFERROR(_xlfn.XLOOKUP(D59,[1]LPU!$C:$C,[1]LPU!$D:$D)*Orçamento_Padrão!E59,F59) -> 0
H60: =IFERROR(_xlfn.XLOOKUP(D60,[1]LPU!$C:$C,[1]LPU!$D:$D)*Orçamento_Padrão!E60,F60) -> 0
H61: =IFERROR(_xlfn.XLOOKUP(D61,[1]LPU!$C:$C,[1]LPU!$D:$D)*Orçamento_Padrão!E61,F61) -> 0
H62: =IFERROR(_xlfn.XLOOKUP(D62,[1]LPU!$C:$C,[1]LPU!$D:$D)*Orçamento_Padrão!E62,F62) -> 0
H63: =IFERROR(_xlfn.XLOOKUP(D63,[1]LPU!$C:$C,[1]LPU!$D:$D)*Orçamento_Padrão!E63,F63) -> 0
H64: =IFERROR(_xlfn.XLOOKUP(D64,[1]LPU!$C:$C,[1]LPU!$D:$D)*Orçamento_Padrão!E64,F64) -> 0
H65: =IFERROR(_xlfn.XLOOKUP(D65,[1]LPU!$C:$C,[1]LPU!$D:$D)*Orçamento_Padrão!E65,F65) -> 0
H66: =IFERROR(_xlfn.XLOOKUP(D66,[1]LPU!$C:$C,[1]LPU!$D:$D)*Orçamento_Padrão!E66,F66) -> 0
H67: =IFERROR(_xlfn.XLOOKUP(D67,[1]LPU!$C:$C,[1]LPU!$D:$D)*Orçamento_Padrão!E67,F67) -> 0
H68: =IFERROR(_xlfn.XLOOKUP(D68,[1]LPU!$C:$C,[1]LPU!$D:$D)*Orçamento_Padrão!E68,F68) -> 0
H69: =IFERROR(_xlfn.XLOOKUP(D69,[1]LPU!$C:$C,[1]LPU!$D:$D)*Orçamento_Padrão!E69,F69) -> 0
H70: =IFERROR(_xlfn.XLOOKUP(D70,[1]LPU!$C:$C,[1]LPU!$D:$D)*Orçamento_Padrão!E70,F70) -> 0
...

Sheet LPU
A1: TIPO DE SERVIÇOS | B1: DESCRIÇÃO PARA CARTA DE AVARIAS | C1: VALOR
A2: Bateria | B2: Troca de Bateria Automotiva | C2: SOB CONSULTA
A3: Chave principal | B3: Reposição da Chave Principal do Veículo | C3: SOB CONSULTA
A4: Chave reserva | B4: Reposição da Chave Reserva do Veículo | C4: SOB CONSULTA
A5: Macaco (veiculo pesado) | B5: Reposição de macaco automotivo | C5: SOB CONSULTA
A6: Chave de Roda | B6: Reposição de Chave de Roda | C6: R$80,00
A7: Mão de obra para troca de peças fixas da lataria que necessitam de solda (Teto, Laterais, Colunas, Caixa de ar) | B7: Mão de obra para troca de teto com solda | C7: R$750,00
A8: Mão de obra para troca de peças fixas da lataria que necessitam de solda (Teto, Laterais, Colunas, Caixa de ar) | B8: Mão de obra para troca de lateral esquerda com solda | C8: R$750,00
A9: Mão de obra para troca de peças fixas da lataria que necessitam de solda (Teto, Laterais, Colunas, Caixa de ar) | B9: Mão de obra para troca de lateral direita com solda | C9: R$750,00
A10: Mão de obra para troca de peças fixas da lataria que necessitam de solda (Teto, Laterais, Colunas, Caixa de ar) | B10: Mão de obra para troca de coluna dianteira esquerda com solda | C10: R$750,00
A11: Mão de obra para troca de peças fixas da lataria que necessitam de solda (Teto, Laterais, Colunas, Caixa de ar) | B11: Mão de obra para troca de coluna dianteira direita com solda | C11: R$750,00
A12: Mão de obra para troca de peças fixas da lataria que necessitam de solda (Teto, Laterais, Colunas, Caixa de ar) | B12: Mão de obra para troca de coluna traseira esquerda com solda | C12: R$750,00
... A78: Higienização Interna | B78: Serviço de Higienização Interna | C78: R$250,00
A79: Higienização Interna (em caso de sujeira severa será acrescentado R$150) | B79: Serviço de Higienização Interna (Sujeira Severa) | C79: 400
A80: Polimento (Veículos pequenos e médios) | B80: Serviço de Polimento | C80: R$250,00
A81: Martelinho de ouro (Amassado que não afetou a pintura) | B81: Serviço de martelinho de ouro – Capô | C81: R$230,00
A82: Martelinho de ouro (Amassado que não afetou a pintura) | B82: Serviço de martelinho de ouro – Teto | C82: R$230,00
A83: Martelinho de ouro (Amassado que não afetou a pintura) | B83: Serviço de martelinho de ouro – Porta dianteira esquerda | C83: R$230,00
A84: Martelinho de ouro (Amassado que não afetou a pintura) | B84: Serviço de martelinho de ouro – Porta dianteira direita | C84: R$230,00
A85: Martelinho de ouro (Amassado que não afetou a pintura) | B85: Serviço de martelinho de ouro – Porta traseira esquerda | C85: R$230,00
A86: Martelinho de ouro (Amassado que não afetou a pintura) | B86: Serviço de martelinho de ouro – Porta traseira direita | C86: R$230,00
A87: Martelinho de ouro (Amassado que não afetou a pintura) | B87: Serviço de martelinho de ouro – Paralama dianteiro esquerdo | C87: R$230,00
A88: Martelinho de ouro (Amassado que não afetou a pintura) | B88: Serviço de martelinho de ouro – Paralama dianteiro direito | C88: R$230,00
A89: Martelinho de ouro (Amassado que não afetou a pintura) | B89: Serviço de martelinho de ouro – Paralama traseiro esquerdo | C89: R$230,00
A90: Martelinho de ouro (Amassado que não afetou a pintura) | B90: Serviço de martelinho de ouro – Paralama traseiro direito | C90: R$230,00
A91: Martelinho de ouro (Amassado que não afetou a pintura) | B91: Serviço de martelinho de ouro – Tampa do porta-malas | C91: R$230,00
... A137: Mão de obra para troca de peças moveis que não necessitam de solda (Parachoques, Paralamas, Porta, Capô, Tampa traseira, Lanternas, Farois e Retrovisores) | B137: Mão de obra para troca de Farol direito | C137: R$140,00
A138: Mão de obra para troca de peças moveis que não necessitam de solda (Parachoques, Paralamas, Porta, Capô, Tampa traseira, Lanternas, Farois e Retrovisores) | B138: Mão de obra para troca de Farol de neblina direito
A139: Mão de obra para troca de peças moveis que não necessitam de solda (Parachoques, Paralamas, Porta, Capô, Tampa traseira, Lanternas, Farois e Retrovisores) | B139: Mão de obra para troca de Farol de neblina esquerdo
A140: Mão de obra para troca de peças moveis que não necessitam de solda (Parachoques, Paralamas, Porta, Capô, Tampa traseira, Lanternas, Farois e Retrovisores) | B140: Mão de obra para troca de Retrovisor esquerdo | C140: R$140,00
A141: Mão de obra para troca de peças moveis que não necessitam de solda (Parachoques, Paralamas, Porta, Capô, Tampa traseira, Lanternas, Farois e Retrovisores) | B141: Mão de obra para troca de Retrovisor direito | C141: R$140,00
A142: Mão de obra para troca de peças moveis que não necessitam de solda (Parachoques, Paralamas, Porta, Capô, Tampa traseira, Lanternas, Farois e Retrovisores) | B142: Mão de obra para troca de repetidor de seta direito | C142: R$140,00
A143: Mão de obra para troca de peças moveis que não necessitam de solda (Parachoques, Paralamas, Porta, Capô, Tampa traseira, Lanternas, Farois e Retrovisores) | B143: Mão de obra para troca de repetidor de seta esquerdo | C143: R$140,00
A144: Martelinho de ouro (por peça, com até 3 mossas) | B144: Serviço de martelinho de ouro – Capô | C144: R$140,00
A145: Martelinho de ouro (por peça, com até 3 mossas) | B145: Serviço de martelinho de ouro – Teto | C145: R$140,00
A146: Martelinho de ouro (por peça, com até 3 mossas) | B146: Serviço de martelinho de ouro – Porta dianteira esquerda | C146: R$140,00
A147: Martelinho de ouro (por peça, com até 3 mossas) | B147: Serviço de martelinho de ouro – Porta dianteira direita | C147: R$140,00
A148: Martelinho de ouro (por peça, com até 3 mossas) | B148: Serviço de martelinho de ouro – Porta traseira esquerda | C148: R$140,00
A149: Martelinho de ouro (por peça, com até 3 mossas) | B149: Serviço de martelinho de ouro – Porta traseira direita | C149: R$140,00
A150: Martelinho de ouro (por peça, com até 3 mossas) | B150: Serviço de martelinho de ouro – Paralama dianteiro esquerdo | C150: R$140,00
...

Sheet Detalhamento_Avarias
B2: Detalhamento da Cobrança
B7: Cliente | C7: xxxx
B8: Contrato: | C8: xxxx
B10: Placa: | C10: RTB4D20 | K10: VALOR TOTAL
B11: Modelo: | C11: MOBI LIKE 1.0 8V FLEX 4P C/AR | K11: 760
B12: Cor: | C12: CINZA SILVERSTONE
B16: 1 | C16: Recuperação e pintura porta dianteira direita | J16: Valor | K16: 420
B32: 2 | C32: Pintura porta dianteira esquerda | J32: Valor | K32: 340

Sheet Checklist
B7: TITAN PNEUS DO BRASIL LTDA
B8: SAO0902/15
B12: RUP2D06
B13: SW4 DIAMOND 7L 2.8 16V TURBO DIE 4X4 4P C/AR - AUTOMÁTICO BLINDADO
B14: BRANCO PEROLIZADO COM TETO PRETO
C20: Polimento | G20: 250
